Workbook

Sheet Sheet1
A1: cust_id | B1: status cust_id | C1: Classificação Atual | D1: deals group on wpp? | E1: link | F1: Tipo Link | G1: URL Corrigida
A2: 84848607 | B2: Confirmado | C2: KAM - top 1000 | D2: Sim | E2: https://chat.whatsapp.com/LBBRUqRFNeQElNvFBIvGiD | F2: Link Quebrado
A3: 94733098 | B3: Confirmado | C3: KAM - top 1000 | D3: Sim | E3: https://chat.whatsapp.com/IR0gCURtqgZAJGne6meFbh | F3: Grupo
A4: 224168003 | B4: Confirmado | C4: KAM - top 1000 | D4: Sim | E4: https://www.whatsapp.com/channel/0029VamngXq6xCSIPEEtlw01 https://www.whatsapp.com/channel/0029VatvEAm3LdQSgVnsaV3X https://chat.whatsapp.com/JVIE5k7qfd3J3UDC0iotAD | F4: Misto
A5: 288063877 | B5: Confirmado | C5: KAM - top 1000 | D5: Sim | E5: https://chat.whatsapp.com/FYshNVla9hcBWbSoIwfGm3 | F5: Grupo
A6: 473343832 | B6: Confirmado | C6: KAM - top 1000 | D6: Sim | E6: https://chat.whatsapp.com/KvP3btvte3j6t7w7m9Q6h7 | F6: Grupo
A7: 1299080285 | B7: Confirmado | C7: KAM - top 1000 | D7: Sim | E7: https://achadinhosimperdiveis.com.br/achadinho-grupo | F7: Grupo
A8: 1334764746 | B8: Confirmado | C8: KAM - top 1000 | D8: Sim | E8: https://chat.whatsapp.com/EuscaPvDB4t2rTAC1gSG05 | F8: Grupo
A9: 1374758175 | B9: Confirmado | C9: KAM - top 1000 | D9: Sim | E9: https://sndflw.com/i/grupospromotop | F9: Grupo
A10: 1399249654 | B10: Confirmado | C10: KAM - top 1000 | D10: Sim | E10: l.instagram.com/?u=https%3A%2F%2Fwhatsapp.com%2Fchannel%2F0029Vb6XAspJ3juxxcp3UH1i%3Ffbclid%3DPAZXh0bgNhZW0CMTEAAadBdK77zRWg5sZktionHSexH5za-rLvFztWXI3mhVIBOTXbG2kRXJWPnC65VQ_aem_ke8foGBPJza_P58nBxfqqg&e=AT10GY-UGrn6D2i2SinDN0XgE7irReo8I-g3uQY097DN-WeG7aoFXDZopMQ0OwgnczwdqC8il0xWCJUkQDB1U0YEBdUUeir4QcCgDOg9xg | F10: Canal
A11: 1428402957 | B11: Confirmado | C11: KAM - top 1000 | D11: Sim | E11: https://chat.whatsapp.com/Itr0HHBK6I7Gwt1oJ7FyUy?mode=wwc | F11: Grupo
A12: 1438016577 | B12: Confirmado | C12: KAM - top 1000 | D12: Sim | E12: https://chat.whatsapp.com/ELd5ipGU0HnGR2nsuZzCOw | F12: Grupo
A13: 1463526269 | B13: Confirmado | C13: KAM - top 1000 | D13: Sim | E13: https://chat.whatsapp.com/EfbYI7XUWZA1KcK89zgygE?mode=ems_copy_t | F13: Grupo
... A33: 2359144247 | B33: Confirmado | C33: KAM - top 1000 | D33: Sim | E33: https://chat.whatsapp.com/Lvt6ezs2Fz6ItqKyCW6JE6?mode=ems_copy_c&fbclid=PAZXh0bgNhZW0CMTEAAaecVIipIqzPHpM9TWnQt9z5lLbf8yw0MVN9vTjW7esIEjh9DNIm2Xb8mIN4kw_aem__bvkExuwYQzmobqnHbOmOA | F33: Grupo
A34: 1813105314 | B34: Confirmado | C34: KAM - top 1000 | D34: Sim | E34: https://i.sendflow.pro/invite/GrupoDaGaaby?utm_id=1344207247310791_v2_s01_e1001&fbclid=PAZXh0bgNhZW0CMTEAAadI0I5Xxqj2d3cC6QNpTKVu3GVOoWRpweL6ejiN9j8h_70LcVId0QaDQyabog_aem_OHbflDNFGlrp5Hutuk-rCQ | F34: Grupo | G34: https://chat.whatsapp.com/FFBssTAsJUe5S1fdCPjfjU
A35: 1377978276 | B35: Confirmado | C35: KAM - top 1000 | D35: Sim | E35: https://chat.whatsapp.com/Ks3048s1gRjGzqfnbOmRKs | F35: Grupo
A36: 1494770433 | B36: Confirmado | C36: KAM - top 1000 | D36: Sim | E36: https://chat.whatsapp.com/Bye3jMn7cOa7YkeymQIZIC?mode=wwt | F36: Grupo
A37: 1478707361 | B37: Confirmado | C37: KAM - top 1000 | D37: Sim | E37: https://chat.whatsapp.com/GANhutgr55J95N65Xb6Lk3 | F37: Grupo
A38: 512970471 | B38: Confirmado | C38: KAM - top 1000 | D38: Sim | E38: https://chat.whatsapp.com/D6vTMhtpTji4R4oJ1oBcB2 | F38: Grupo
A39: 1408672391 | B39: Confirmado | C39: KAM - top 1000 | D39: Sim | E39: https://chat.whatsapp.com/HlzrhZslJCZ6YVTSRDI71M?fbclid=PAZXh0bgNhZW0CMTEAAaeHCVvc7x51MYFXyqM5U8Vp142hYcrnX9m3TEYGypZ49CY9XKSMc1l0jIISvQ_aem_SWfxcvpL11OpZOE0WOljRg | F39: Grupo
A40: 1446956733 | B40: Confirmado | C40: KAM - top 1000 | D40: Sim | E40: https://chat.whatsapp.com/DSeLEmy3Ccg2cQIQu0PZIg | F40: Grupo
A41: 226046758 | B41: Confirmado | C41: KAM - top 1000 | D41: Sim | E41: https://chat.whatsapp.com/JMfX31vfU1BBh6cf7R0Uqo | F41: Grupo
A42: 150242200 | B42: Confirmado | C42: KAM - top 1000 | D42: Sim | E42: https://chat.whatsapp.com/DFpRm2RkKfFGpYfqLxWcAo | F42: Grupo
A43: 269721398 | B43: Confirmado | C43: KAM - top 1000 | D43: Sim | E43: https://chat.whatsapp.com/FKCP03nC7DLKYr1sonRws9 | F43: Grupo
A44: 1516990091 | B44: Confirmado | C44: KAM - top 1000 | D44: Sim | E44: https://chat.whatsapp.com/FJpxwCaPLyO6VJjgSQPRRo?mode=ac_t | F44: Grupo
A45: 379432988 | B45: Confirmado | C45: KAM - top 1000 | D45: Sim | E45: http://chat.whatsapp.com/FuRrPRMeses2RqaTpBagwf https://chat.whatsapp.com/LiJjq9uEt07Hf6EXIc4LQp | F45: Grupo
A46: 1433577301 | B46: Confirmado | C46: KAM - top 1000 | D46: Sim | E46: https://t.me/promotom | F46: Conversa
... A56: 1541281221 | B56: Confirmado | C56: KAM - top 1000 | D56: Sim | E56: https://t.me/hardmoboficial?fbclid=PAZXh0bgNhZW0CMTEAAad91QlFMoxqd5UJjboP1N62cWtANiGM8E-vBGNaFAYTv22PVy_IgmIAYP2ncA_aem_dIDit8IE-_yP-KhZd8qrvw | F56: Telegram
A57: 618183409 | B57: Confirmado | C57: KAM - top 1000 | D57: Sim | E57: app.gruposinteligentes.com/r/achadosdaccarol | F57: Grupo | G57: https://chat.whatsapp.com/JUkT4DzEq8E2qKDq8gUQNV
A58: 1954038151 | B58: Confirmado | C58: KAM - top 1000 | D58: Sim | E58: https://chat.whatsapp.com/GUgEwbuk86aJDdyJfLsSQ3 | F58: Grupo
A59: 744048622 | B59: Confirmado | C59: KAM - top 1000 | D59: Sim | E59: https://chat.whatsapp.com/BZpAuh2smnSBgAMWUIr8it | F59: Grupo
A60: 79019768 | B60: Confirmado | C60: KAM - top 1000 | D60: Sim | E60: https://chat.whatsapp.com/CMPA3hBbXmSBg7aEoHcdAc | F60: Grupo
A61: 521028663 | B61: Confirmado | C61: KAM - top 1000 | D61: Sim | E61: https://chat.whatsapp.com/JHaBQhjiioN4q54FVbHTv0 | F61: Grupo
A62: 1578049413 | B62: Confirmado | C62: KAM - top 1000 | D62: Sim | E62: https://t.me/outletblackfriday?fbclid=PAZXh0bgNhZW0CMTEAAac47Msicc8FXyO3GJEJp7W7OpkgNlER3DQHosVikFjue5nnEBRylCDqCn4shg_aem_6FHXolLGMvNQDjPKiROTIw | F62: Telegram
A63: 1442794904 | B63: Confirmado | C63: KAM - top 1000 | D63: Sim | E63: https://t.me/economizanderson?fbclid=PAZXh0bgNhZW0CMTEAAaef6d27dw2ja87QTtQO_MnMQVpnvTWC5XNp7DI3yRcBqkCTEbNwFlDejv1mCg_aem_HUyi1kmKQpZ1Kp3U_gcqJQ | F63: Telegram
A64: 136554975 | B64: Confirmado | C64: KAM - top 1000 | D64: Sim | E64: https://chat.whatsapp.com/CCbeOEcw45ZIS7Du8dZchQ | F64: Grupo
A65: 1550052320 | B65: Confirmado | C65: KAM - top 1000 | D65: Sim | E65: https://chat.whatsapp.com/K41Nfk48Mid9cAN7OA1V3K | F65: Grupo
A66: 92792646 | B66: Confirmado | C66: KAM - top 1000 | D66: Sim | E66: https://chat.whatsapp.com/Hi4wsoxm8oyDgk09a0zpEW?mode=wwc | F66: Grupo
A67: 192874049 | B67: Confirmado | C67: KAM - top 1000 | D67: Sim | E67: https://t.me/guigatudo?fbclid=PAZXh0bgNhZW0CMTEAAacBjHWdgbtIiHfb7eVYEP7x7VJoopp-_VAx_bvrD99Tkr_EbdNI1HnzpiKmUQ_aem_4ywXVHc8170ntvYwuqnUjA | F67: Telegram
A68: 481509072 | B68: Confirmado | C68: KAM - top 1000 | D68: Sim | E68: https://chat.whatsapp.com/Hjr3f7J3jCB5dxUy4DqPpl?mode=wwc | F68: Grupo
...

Sheet Tech e Cross
A1: cus_cust_id_aff | B1: aff_name | C1: Check | D1: rede 1 | E1: rede 2 | F1: grupo
A2: 488851324 | B2: promosdodia | C2: {=IFERROR(_xludf.XLOOKUP(A2,Sheet1!A:A,Sheet1!B:B),"Não")} -> Não | D2: {=_xludf.XLOOKUP(A2,import!A:A,import!C:C)} -> #NAME? | E2: {=_xludf.XLOOKUP(A2,import!A:A,import!E:E)} -> #NAME?
A3: 2490611911 | B3: promozonevip | C3: {=IFERROR(_xludf.XLOOKUP(A3,Sheet1!A:A,Sheet1!B:B),"Não")} -> Não | D3: {=_xludf.XLOOKUP(A3,import!A:A,import!C:C)} -> #NAME? | E3: {=_xludf.XLOOKUP(A3,import!A:A,import!E:E)} -> #NAME? | F3: https://www.whatsapp.com/channel/0029VbBuyGKCxoAyO2Utji3k
A4: 1477497679 | B4: minutoreview | C4: {=IFERROR(_xludf.XLOOKUP(A4,Sheet1!A:A,Sheet1!B:B),"Não")} -> Não | D4: {=_xludf.XLOOKUP(A4,import!A:A,import!C:C)} -> #NAME? | E4: {=_xludf.XLOOKUP(A4,import!A:A,import!E:E)} -> #NAME? | F4: https://t.me/heroidapromo
A5: 555414187 | B5: Xetdaspromocoes | C5: {=IFERROR(_xludf.XLOOKUP(A5,Sheet1!A:A,Sheet1!B:B),"Não")} -> Não | D5: {=_xludf.XLOOKUP(A5,import!A:A,import!C:C)} -> #NAME? | E5: {=_xludf.XLOOKUP(A5,import!A:A,import!E:E)} -> #NAME? | F5: https://tr.ee/uRb7a25vid
A6: 1236298302 | B6: jersu | C6: {=IFERROR(_xludf.XLOOKUP(A6,Sheet1!A:A,Sheet1!B:B),"Não")} -> Não | D6: {=_xludf.XLOOKUP(A6,import!A:A,import!C:C)} -> #NAME? | E6: {=_xludf.XLOOKUP(A6,import!A:A,import!E:E)} -> #NAME? | F6: https://chat.whatsapp.com/DEvLKnMXcn11I4VonM1GbH
A7: 1245410086 | B7: tukemperial | C7: {=IFERROR(_xludf.XLOOKUP(A7,Sheet1!A:A,Sheet1!B:B),"Não")} -> Não | D7: {=_xludf.XLOOKUP(A7,import!A:A,import!C:C)} -> #NAME? | E7: {=_xludf.XLOOKUP(A7,import!A:A,import!E:E)} -> #NAME?
A8: 1231808348 | B8: gesiel | C8: {=IFERROR(_xludf.XLOOKUP(A8,Sheet1!A:A,Sheet1!B:B),"Não")} -> Não | D8: {=_xludf.XLOOKUP(A8,import!A:A,import!C:C)} -> #NAME? | E8: {=_xludf.XLOOKUP(A8,import!A:A,import!E:E)} -> #NAME? | F8: https://www.whatsapp.com/channel/0029VaEPqqBDOQIUTTOCMg1l
A9: 1406524799 | B9: Toptech | C9: {=IFERROR(_xludf.XLOOKUP(A9,Sheet1!A:A,Sheet1!B:B),"Não")} -> Não | D9: {=_xludf.XLOOKUP(A9,import!A:A,import!C:C)} -> #NAME? | E9: {=_xludf.XLOOKUP(A9,import!A:A,import!E:E)} -> #NAME?
A10: 1464475202 | B10: joaopsx | C10: {=IFERROR(_xludf.XLOOKUP(A10,Sheet1!A:A,Sheet1!B:B),"Não")} -> Não | D10: {=_xludf.XLOOKUP(A10,import!A:A,import!C:C)} -> #NAME? | E10: {=_xludf.XLOOKUP(A10,import!A:A,import!E:E)} -> #NAME? | F10: https://www.whatsapp.com/channel/0029Va9lrS5GufIu669tIy13
A11: 1342859483 | B11: abelhando | C11: {=IFERROR(_xludf.XLOOKUP(A11,Sheet1!A:A,Sheet1!B:B),"Não")} -> Não | D11: {=_xludf.XLOOKUP(A11,import!A:A,import!C:C)} -> #NAME? | E11: {=_xludf.XLOOKUP(A11,import!A:A,import!E:E)} -> #NAME? | F11: https://chat.whatsapp.com/K6CTXebMZ0eJMX8B8uIiA1
A12: 1317961778 | B12: thautec | C12: {=IFERROR(_xludf.XLOOKUP(A12,Sheet1!A:A,Sheet1!B:B),"Não")} -> Não | D12: {=_xludf.XLOOKUP(A12,import!A:A,import!C:C)} -> #NAME? | E12: {=_xludf.XLOOKUP(A12,import!A:A,import!E:E)} -> #NAME? | F12: https://www.whatsapp.com/channel/0029Val8yoECHDyoi2TgYt1z
A13: 1286635153 | B13: economizei | C13: {=IFERROR(_xludf.XLOOKUP(A13,Sheet1!A:A,Sheet1!B:B),"Não")} -> Não | D13: {=_xludf.XLOOKUP(A13,import!A:A,import!C:C)} -> #NAME? | E13: {=_xludf.XLOOKUP(A13,import!A:A,import!E:E)} -> #NAME?
A14: 1445776663 | B14: JCAPUBLICIDADE | C14: {=IFERROR(_xludf.XLOOKUP(A14,Sheet1!A:A,Sheet1!B:B),"Não")} -> Não | D14: {=_xludf.XLOOKUP(A14,import!A:A,import!C:C)} -> #NAME? | E14: {=_xludf.XLOOKUP(A14,import!A:A,import!E:E)} -> #NAME? | F14: https://chat.whatsapp.com/D5RX0sZReSDISIJG4WsZ38
A15: 1211756872 | B15: lipe | C15: {=IFERROR(_xludf.XLOOKUP(A15,Sheet1!A:A,Sheet1!B:B),"Não")} -> Não | D15: {=_xludf.XLOOKUP(A15,import!A:A,import!C:C)} -> #NAME? | E15: {=_xludf.XLOOKUP(A15,import!A:A,import!E:E)} -> #NAME? | F15: https://t.me/lipeofertas
A16: 1207675246 | B16: canalrodrigomoreira | C16: {=IFERROR(_xludf.XLOOKUP(A16,Sheet1!A:A,Sheet1!B:B),"Não")} -> Não | D16: {=_xludf.XLOOKUP(A16,import!A:A,import!C:C)} -> #NAME? | E16: {=_xludf.XLOOKUP(A16,import!A:A,import!E:E)} -> #NAME? | F16: https://chat.whatsapp.com/DYL3yM8t1Qx5ZIRJR3PUh7?mode=ems_copy_t
A17: 1422846329 | B17: coelhonojapo | C17: {=IFERROR(_xludf.XLOOKUP(A17,Sheet1!A:A,Sheet1!B:B),"Não")} -> Não | D17: {=_xludf.XLOOKUP(A17,import!A:A,import!C:C)} -> #NAME? | E17: {=_xludf.XLOOKUP(A17,import!A:A,import!E:E)} -> #NAME? | F17: https://chat.whatsapp.com/Ihx4dPdJUYAAxEmbT1o0Q8
A18: 76331531 | B18: especialistaemti | C18: {=IFERROR(_xludf.XLOOKUP(A18,Sheet1!A:A,Sheet1!B:B),"Não")} -> Não | D18: {=_xludf.XLOOKUP(A18,import!A:A,import!C:C)} -> #NAME? | E18: {=_xludf.XLOOKUP(A18,import!A:A,import!E:E)} -> #NAME? | F18: https://chat.whatsapp.com/LRjdSDkp9jd6OOLSCwY5Qm
A19: 1454842874 | B19: promocaozinha | C19: {=IFERROR(_xludf.XLOOKUP(A19,Sheet1!A:A,Sheet1!B:B),"Não")} -> Não
A20: 593029712 | B20: pobredasofertas | C20: {=IFERROR(_xludf.XLOOKUP(A20,Sheet1!A:A,Sheet1!B:B),"Não")} -> Não
A21: 207302282 | B21: promos4m | C21: {=IFERROR(_xludf.XLOOKUP(A21,Sheet1!A:A,Sheet1!B:B),"Não")} -> Não
A22: 322502351 | B22: desconto | C22: {=IFERROR(_xludf.XLOOKUP(A22,Sheet1!A:A,Sheet1!B:B),"Não")} -> Não | D22: {=_xludf.XLOOKUP(A22,import!A:A,import!C:C)} -> #NAME? | E22: {=_xludf.XLOOKUP(A22,import!A:A,import!E:E)} -> #NAME? | F22: https://t.me/santostecpromo?fbclid=PAZXh0bgNhZW0CMTEAAaeVb188JbMikBC-pCWnnB-AVUWx8S9YKjN0MyENCabECnWM-Txqf-BfQBDA5A_aem_3uUYjDnj73qTV1TlZ3lA3A
A23: 1375138586 | B23: Canaljptech | C23: {=IFERROR(_xludf.XLOOKUP(A23,Sheet1!A:A,Sheet1!B:B),"Não")} -> Não | D23: {=_xludf.XLOOKUP(A23,import!A:A,import!C:C)} -> #NAME? | E23: {=_xludf.XLOOKUP(A23,import!A:A,import!E:E)} -> #NAME? | F23: https://www.whatsapp.com/channel/0029VaDc0VKATRSg2k5sOb0u
A24: 1366151811 | B24: pcdofafa | C24: {=IFERROR(_xludf.XLOOKUP(A24,Sheet1!A:A,Sheet1!B:B),"Não")} -> Não | D24: {=_xludf.XLOOKUP(A24,import!A:A,import!C:C)} -> #NAME? | E24: {=_xludf.XLOOKUP(A24,import!A:A,import!E:E)} -> #NAME? | F24: https://t.me/fafapromoshorts
A25: 1473563772 | B25: urubupromo | C25: {=IFERROR(_xludf.XLOOKUP(A25,Sheet1!A:A,Sheet1!B:B),"Não")} -> Não
A26: 1249172900 | B26: tttech | C26: {=IFERROR(_xludf.XLOOKUP(A26,Sheet1!A:A,Sheet1!B:B),"Não")} -> Não | D26: {=_xludf.XLOOKUP(A26,import!A:A,import!C:C)} -> #NAME? | E26: {=_xludf.XLOOKUP(A26,import!A:A,import!E:E)} -> #NAME? | F26: https://chat.whatsapp.com/Dq1JEvVMkAmJywEcvLbjB8
A27: 1478114661 | B27: peguepromo | C27: {=IFERROR(_xludf.XLOOKUP(A27,Sheet1!A:A,Sheet1!B:B),"Não")} -> Não | D27: {=_xludf.XLOOKUP(A27,import!A:A,import!C:C)} -> #NAME? | E27: {=_xludf.XLOOKUP(A27,import!A:A,import!E:E)} -> #NAME? | F27: Link quebrado
A28: 1231576803 | B28: inovaleo | C28: {=IFERROR(_xludf.XLOOKUP(A28,Sheet1!A:A,Sheet1!B:B),"Não")} -> Não | D28: {=_xludf.XLOOKUP(A28,import!A:A,import!C:C)} -> #NAME? | E28: {=_xludf.XLOOKUP(A28,import!A:A,import!E:E)} -> #NAME? | F28: https://chat.whatsapp.com/JWySm0bg2QjDJwYKymBRAr?mode=wwt
A29: 1450808630 | B29: agenciarice | C29: {=IFERROR(_xludf.XLOOKUP(A29,Sheet1!A:A,Sheet1!B:B),"Não")} -> Não
A30: 1251879558 | B30: qualnotebook | C30: {=IFERROR(_xludf.XLOOKUP(A30,Sheet1!A:A,Sheet1!B:B),"Não")} -> Não | D30: {=_xludf.XLOOKUP(A30,import!A:A,import!C:C)} -> #NAME? | E30: {=_xludf.XLOOKUP(A30,import!A:A,import!E:E)} -> #NAME? | F30: https://chat.whatsapp.com/J5kJyOeNUjnAOla4kweuk4
A31: 2345017244 | B31: promosinc | C31: {=IFERROR(_xludf.XLOOKUP(A31,Sheet1!A:A,Sheet1!B:B),"Não")} -> Não | D31: {=_xludf.XLOOKUP(A31,import!A:A,import!C:C)} -> #NAME? | E31: {=_xludf.XLOOKUP(A31,import!A:A,import!E:E)} -> #NAME? | F31: Link quebrado
A32: 1453452471 | B32: Daniel Reenlsober | C32: {=IFERROR(_xludf.XLOOKUP(A32,Sheet1!A:A,Sheet1!B:B),"Não")} -> Não | D32: {=_xludf.XLOOKUP(A32,import!A:A,import!C:C)} -> #NAME? | E32: {=_xludf.XLOOKUP(A32,import!A:A,import!E:E)} -> #NAME? | F32: https://www.whatsapp.com/channel/0029Va9QFJGICVfkJA730514
A33: 1161200505 | B33: mastertechjr | C33: {=IFERROR(_xludf.XLOOKUP(A33,Sheet1!A:A,Sheet1!B:B),"Não")} -> Não | D33: {=_xludf.XLOOKUP(A33,import!A:A,import!C:C)} -> #NAME? | E33: {=_xludf.XLOOKUP(A33,import!A:A,import!E:E)} -> #NAME? | F33: https://t.me/mastertechjr?fbclid=PAZXh0bgNhZW0CMTEAAaewxnUciKJdSe5Wco9fLTmBaJM1DHn4eoDmr2swvK0goIkep-9zfI_u-Knyhw_aem_0gcMRKOctBIeWR6jSsQ7RQ
A34: 1374758175 | B34: promotop | C34: {=IFERROR(_xludf.XLOOKUP(A34,Sheet1!A:A,Sheet1!B:B),"Não")} -> Não
A35: 268850426 | B35: jeffrecomenda | C35: {=IFERROR(_xludf.XLOOKUP(A35,Sheet1!A:A,Sheet1!B:B),"Não")} -> Não | D35: {=_xludf.XLOOKUP(A35,import!A:A,import!C:C)} -> #NAME? | E35: {=_xludf.XLOOKUP(A35,import!A:A,import!E:E)} -> #NAME? | F35: https://chat.whatsapp.com/EtM3xhWp5wcFuqkVNdLOL1?mode=ac_t&fbclid=PAZXh0bgNhZW0CMTEAAcvKmLCoRYh1JrXVQa4GIsd0EnkbBnFBQ4AcdQWmNVlGTiH5r-fPAM9WgGJDw_aem_9ZENO9O-OpjiO-ebHt4fdA
A36: 1426808500 | B36: promoimperdivel | C36: {=IFERROR(_xludf.XLOOKUP(A36,Sheet1!A:A,Sheet1!B:B),"Não")} -> Não | D36: {=_xludf.XLOOKUP(A36,import!A:A,import!C:C)} -> #NAME? | E36: {=_xludf.XLOOKUP(A36,import!A:A,import!E:E)} -> #NAME? | F36: https://chat.whatsapp.com/IFJMvDHZc2AIYyGqQcEHqt
A37: 1114585317 | B37: bench promos | C37: {=IFERROR(_xludf.XLOOKUP(A37,Sheet1!A:A,Sheet1!B:B),"Não")} -> Não | D37: {=_xludf.XLOOKUP(A37,import!A:A,import!C:C)} -> #NAME? | E37: {=_xludf.XLOOKUP(A37,import!A:A,import!E:E)} -> #NAME? | F37: https://www.whatsapp.com/channel/0029VbBJP9aDzgTBmNHBd62p?fbclid=PAZXh0bgNhZW0CMTEAAae32tBkLXNaDzwchmglVLXLDmLa4onLEK6UMw4op25Tx7lTcIryD6JcBRv1UA_aem_AznNWot3JZd5_PmBAUTuNg
A38: 1370750164 | B38: switchxz | C38: {=IFERROR(_xludf.XLOOKUP(A38,Sheet1!A:A,Sheet1!B:B),"Não")} -> Não | D38: {=_xludf.XLOOKUP(A38,import!A:A,import!C:C)} -> #NAME? | E38: {=_xludf.XLOOKUP(A38,import!A:A,import!E:E)} -> #NAME? | F38: https://t.me/LinksBrazil?fbclid=PAZXh0bgNhZW0CMTEAAaeCZzCU7ct0adx3XBcqEzD56i_Y-W9K4JavWSlJnENQoakUhv1Jo7E97niWAQ_aem_nKvEHacyctGXjbbgz8Qztw
A39: 251645009 | B39: novosprodutos | C39: {=IFERROR(_xludf.XLOOKUP(A39,Sheet1!A:A,Sheet1!B:B),"Não")} -> Não | D39: {=_xludf.XLOOKUP(A39,import!A:A,import!C:C)} -> #NAME? | E39: {=_xludf.XLOOKUP(A39,import!A:A,import!E:E)} -> #NAME? | F39: https://chat.whatsapp.com/GzuMpKwpGqy89P9YL4cu4x?fbclid=PAZXh0bgNhZW0CMTEAAadtVsUG-QmJI9FtehAWBo4gBDhfKLcva3fXquMK1HL2EKTrPPso_iZwcw83BA_aem_5eHhxYVaRpg-LB_H71RvZg
A40: 263391604 | B40: so_promocoesdodia | C40: {=IFERROR(_xludf.XLOOKUP(A40,Sheet1!A:A,Sheet1!B:B),"Não")} -> Não | D40: {=_xludf.XLOOKUP(A40,import!A:A,import!C:C)} -> #NAME? | E40: {=_xludf.XLOOKUP(A40,import!A:A,import!E:E)} -> #NAME? | F40: https://chat.whatsapp.com/Gw5saEcajBS8p7yf7rgDvf?mode=wwc
...

Sheet import
A1: =IFERROR(__xludf.DUMMYFUNCTION("IMPORTRANGE(""https://docs.google.com/spreadsheets/d/10g4G0kCjCDd_ICa4_A1YPT2Qy7lcMrhzmtXWv-RZ8rU/edit?gid=968273440#gid=968273440"",""Gestão Carteira!A2:B2000"")"),"cus_cust_id_aff") -> cus_cust_id_aff | B1: =IFERROR(__xludf.DUMMYFUNCTION("""COMPUTED_VALUE"""),"aff_name") -> aff_name | C1: =IFERROR(__xludf.DUMMYFUNCTION("IMPORTRANGE(""https://docs.google.com/spreadsheets/d/10g4G0kCjCDd_ICa4_A1YPT2Qy7lcMrhzmtXWv-RZ8rU/edit?gid=968273440#gid=968273440"",""Gestão Carteira!AM2:AP2000"")"),"Qual seu Instagram?") -> Qual seu Instagram? | D1: =IFERROR(__xludf.DUMMYFUNCTION("""COMPUTED_VALUE"""),"Quantos seguidores você tem no Instagram?") -> Quantos seguidores você tem no Instagram? | E1: =IFERROR(__xludf.DUMMYFUNCTION("""COMPUTED_VALUE"""),"Qual seu perfil no TikTok?") -> Qual seu perfil no TikTok? | F1: =IFERROR(__xludf.DUMMYFUNCTION("""COMPUTED_VALUE"""),"Quantos seguidores você tem no TikTok?") -> Quantos seguidores você tem no TikTok?
A2: =IFERROR(__xludf.DUMMYFUNCTION("""COMPUTED_VALUE"""),488851324) -> 488851324 | B2: =IFERROR(__xludf.DUMMYFUNCTION("""COMPUTED_VALUE"""),"promosdodia") -> promosdodia | C2: =IFERROR(__xludf.DUMMYFUNCTION("""COMPUTED_VALUE"""),"") | D2: =IFERROR(__xludf.DUMMYFUNCTION("""COMPUTED_VALUE"""),"") | E2: =IFERROR(__xludf.DUMMYFUNCTION("""COMPUTED_VALUE"""),"") | F2: =IFERROR(__xludf.DUMMYFUNCTION("""COMPUTED_VALUE"""),"")
A3: =IFERROR(__xludf.DUMMYFUNCTION("""COMPUTED_VALUE"""),2490611911) -> 2490611911 | B3: =IFERROR(__xludf.DUMMYFUNCTION("""COMPUTED_VALUE"""),"promozonevip") -> promozonevip | C3: =IFERROR(__xludf.DUMMYFUNCTION("""COMPUTED_VALUE"""),"https://www.instagram.com/eusoubarone?igsh=cWVvOXQydzdseW15") -> https://www.instagram.com/eusoubarone?igsh=cWVvOXQydzdseW15 | D3: =IFERROR(__xludf.DUMMYFUNCTION("""COMPUTED_VALUE"""),4000000) -> 4000000
A4: =IFERROR(__xludf.DUMMYFUNCTION("""COMPUTED_VALUE"""),1477497679) -> 1477497679 | B4: =IFERROR(__xludf.DUMMYFUNCTION("""COMPUTED_VALUE"""),"minutoreview") -> minutoreview | C4: =IFERROR(__xludf.DUMMYFUNCTION("""COMPUTED_VALUE"""),"https://www.instagram.com/heroidapromo/") -> https://www.instagram.com/heroidapromo/ | D4: =IFERROR(__xludf.DUMMYFUNCTION("""COMPUTED_VALUE"""),147000) -> 147000
A5: =IFERROR(__xludf.DUMMYFUNCTION("""COMPUTED_VALUE"""),555414187) -> 555414187 | B5: =IFERROR(__xludf.DUMMYFUNCTION("""COMPUTED_VALUE"""),"Xetdaspromocoes") -> Xetdaspromocoes | C5: =IFERROR(__xludf.DUMMYFUNCTION("""COMPUTED_VALUE"""),"https://x.com/xetdaspromocoes") -> https://x.com/xetdaspromocoes | D5: =IFERROR(__xludf.DUMMYFUNCTION("""COMPUTED_VALUE"""),500000) -> 500000
A6: =IFERROR(__xludf.DUMMYFUNCTION("""COMPUTED_VALUE"""),1236298302) -> 1236298302 | B6: =IFERROR(__xludf.DUMMYFUNCTION("""COMPUTED_VALUE"""),"jersu") -> jersu | C6: =IFERROR(__xludf.DUMMYFUNCTION("""COMPUTED_VALUE"""),"https://www.instagram.com/jeersu") -> https://www.instagram.com/jeersu | D6: =IFERROR(__xludf.DUMMYFUNCTION("""COMPUTED_VALUE"""),171000) -> 171000 | E6: =IFERROR(__xludf.DUMMYFUNCTION("""COMPUTED_VALUE"""),"https://www.tiktok.com/@jersu") -> https://www.tiktok.com/@jersu | F6: =IFERROR(__xludf.DUMMYFUNCTION("""COMPUTED_VALUE"""),114000) -> 114000
A7: =IFERROR(__xludf.DUMMYFUNCTION("""COMPUTED_VALUE"""),1245410086) -> 1245410086 | B7: =IFERROR(__xludf.DUMMYFUNCTION("""COMPUTED_VALUE"""),"tukemperial") -> tukemperial | C7: =IFERROR(__xludf.DUMMYFUNCTION("""COMPUTED_VALUE"""),"") | D7: =IFERROR(__xludf.DUMMYFUNCTION("""COMPUTED_VALUE"""),"") | E7: =IFERROR(__xludf.DUMMYFUNCTION("""COMPUTED_VALUE"""),"") | F7: =IFERROR(__xludf.DUMMYFUNCTION("""COMPUTED_VALUE"""),"")
A8: =IFERROR(__xludf.DUMMYFUNCTION("""COMPUTED_VALUE"""),1231808348) -> 1231808348 | B8: =IFERROR(__xludf.DUMMYFUNCTION("""COMPUTED_VALUE"""),"gesiel") -> gesiel | C8: =IFERROR(__xludf.DUMMYFUNCTION("""COMPUTED_VALUE"""),"https://www.instagram.com/gesieltaveira/") -> https://www.instagram.com/gesieltaveira/ | D8: =IFERROR(__xludf.DUMMYFUNCTION("""COMPUTED_VALUE"""),388000) -> 388000 | E8: =IFERROR(__xludf.DUMMYFUNCTION("""COMPUTED_VALUE"""),"https://www.tiktok.com/@gesieltaveira") -> https://www.tiktok.com/@gesieltaveira | F8: =IFERROR(__xludf.DUMMYFUNCTION("""COMPUTED_VALUE"""),267600) -> 267600
A9: =IFERROR(__xludf.DUMMYFUNCTION("""COMPUTED_VALUE"""),1406524799) -> 1406524799 | B9: =IFERROR(__xludf.DUMMYFUNCTION("""COMPUTED_VALUE"""),"Toptech") -> Toptech | C9: =IFERROR(__xludf.DUMMYFUNCTION("""COMPUTED_VALUE"""),"") | D9: =IFERROR(__xludf.DUMMYFUNCTION("""COMPUTED_VALUE"""),"") | E9: =IFERROR(__xludf.DUMMYFUNCTION("""COMPUTED_VALUE"""),"") | F9: =IFERROR(__xludf.DUMMYFUNCTION("""COMPUTED_VALUE"""),"")
A10: =IFERROR(__xludf.DUMMYFUNCTION("""COMPUTED_VALUE"""),1464475202) -> 1464475202 | B10: =IFERROR(__xludf.DUMMYFUNCTION("""COMPUTED_VALUE"""),"joaopsx") -> joaopsx | C10: =IFERROR(__xludf.DUMMYFUNCTION("""COMPUTED_VALUE"""),"https://www.instagram.com/joao_psx/") -> https://www.instagram.com/joao_psx/ | D10: =IFERROR(__xludf.DUMMYFUNCTION("""COMPUTED_VALUE"""),30000) -> 30000 | E10: =IFERROR(__xludf.DUMMYFUNCTION("""COMPUTED_VALUE"""),"https://www.tiktok.com/@joaopsx") -> https://www.tiktok.com/@joaopsx | F10: =IFERROR(__xludf.DUMMYFUNCTION("""COMPUTED_VALUE"""),15000) -> 15000
A11: =IFERROR(__xludf.DUMMYFUNCTION("""COMPUTED_VALUE"""),1342859483) -> 1342859483 | B11: =IFERROR(__xludf.DUMMYFUNCTION("""COMPUTED_VALUE"""),"abelhando") -> abelhando | C11: =IFERROR(__xludf.DUMMYFUNCTION("""COMPUTED_VALUE"""),"https://www.instagram.com/vrltecnologia/") -> https://www.instagram.com/vrltecnologia/ | D11: =IFERROR(__xludf.DUMMYFUNCTION("""COMPUTED_VALUE"""),3000) -> 3000 | E11: =IFERROR(__xludf.DUMMYFUNCTION("""COMPUTED_VALUE"""),"https://www.tiktok.com/@vrltecnologia") -> https://www.tiktok.com/@vrltecnologia | F11: =IFERROR(__xludf.DUMMYFUNCTION("""COMPUTED_VALUE"""),5000) -> 5000
A12: =IFERROR(__xludf.DUMMYFUNCTION("""COMPUTED_VALUE"""),1317961778) -> 1317961778 | B12: =IFERROR(__xludf.DUMMYFUNCTION("""COMPUTED_VALUE"""),"thautec") -> thautec | C12: =IFERROR(__xludf.DUMMYFUNCTION("""COMPUTED_VALUE"""),"www.instagram.com/thautec") -> www.instagram.com/thautec | D12: =IFERROR(__xludf.DUMMYFUNCTION("""COMPUTED_VALUE"""),500000) -> 500000 | E12: =IFERROR(__xludf.DUMMYFUNCTION("""COMPUTED_VALUE"""),"www.tiktok.com/@thautec") -> www.tiktok.com/@thautec | F12: =IFERROR(__xludf.DUMMYFUNCTION("""COMPUTED_VALUE"""),290000) -> 290000
A13: =IFERROR(__xludf.DUMMYFUNCTION("""COMPUTED_VALUE"""),1286635153) -> 1286635153 | B13: =IFERROR(__xludf.DUMMYFUNCTION("""COMPUTED_VALUE"""),"economizei") -> economizei | C13: =IFERROR(__xludf.DUMMYFUNCTION("""COMPUTED_VALUE"""),"") | D13: =IFERROR(__xludf.DUMMYFUNCTION("""COMPUTED_VALUE"""),"") | E13: =IFERROR(__xludf.DUMMYFUNCTION("""COMPUTED_VALUE"""),"") | F13: =IFERROR(__xludf.DUMMYFUNCTION("""COMPUTED_VALUE"""),"")
A14: =IFERROR(__xludf.DUMMYFUNCTION("""COMPUTED_VALUE"""),1445776663) -> 1445776663 | B14: =IFERROR(__xludf.DUMMYFUNCTION("""COMPUTED_VALUE"""),"JCAPUBLICIDADE") -> JCAPUBLICIDADE | C14: =IFERROR(__xludf.DUMMYFUNCTION("""COMPUTED_VALUE"""),"instagram.com/grupotabugado") -> instagram.com/grupotabugado | D14: =IFERROR(__xludf.DUMMYFUNCTION("""COMPUTED_VALUE"""),31500) -> 31500
A15: =IFERROR(__xludf.DUMMYFUNCTION("""COMPUTED_VALUE"""),1211756872) -> 1211756872 | B15: =IFERROR(__xludf.DUMMYFUNCTION("""COMPUTED_VALUE"""),"lipe") -> lipe | C15: =IFERROR(__xludf.DUMMYFUNCTION("""COMPUTED_VALUE"""),"https://www.instagram.com/lipemalestar/") -> https://www.instagram.com/lipemalestar/ | D15: =IFERROR(__xludf.DUMMYFUNCTION("""COMPUTED_VALUE"""),129000) -> 129000 | E15: =IFERROR(__xludf.DUMMYFUNCTION("""COMPUTED_VALUE"""),"https://www.tiktok.com/@lipemalestar") -> https://www.tiktok.com/@lipemalestar | F15: =IFERROR(__xludf.DUMMYFUNCTION("""COMPUTED_VALUE"""),469000) -> 469000
A16: =IFERROR(__xludf.DUMMYFUNCTION("""COMPUTED_VALUE"""),1207675246) -> 1207675246 | B16: =IFERROR(__xludf.DUMMYFUNCTION("""COMPUTED_VALUE"""),"canalrodrigomoreira") -> canalrodrigomoreira | C16: =IFERROR(__xludf.DUMMYFUNCTION("""COMPUTED_VALUE"""),"www.instagram.com/canalrodrigomoreira") -> www.instagram.com/canalrodrigomoreira | D16: =IFERROR(__xludf.DUMMYFUNCTION("""COMPUTED_VALUE"""),34000) -> 34000 | E16: =IFERROR(__xludf.DUMMYFUNCTION("""COMPUTED_VALUE"""),"www.tiktok.com/@canalrodrigomoreira") -> www.tiktok.com/@canalrodrigomoreira | F16: =IFERROR(__xludf.DUMMYFUNCTION("""COMPUTED_VALUE"""),135000) -> 135000
A17: =IFERROR(__xludf.DUMMYFUNCTION("""COMPUTED_VALUE"""),1422846329) -> 1422846329 | B17: =IFERROR(__xludf.DUMMYFUNCTION("""COMPUTED_VALUE"""),"coelhonojapo") -> coelhonojapo | C17: =IFERROR(__xludf.DUMMYFUNCTION("""COMPUTED_VALUE"""),"https://www.instagram.com/rodrigocoelhoc/") -> https://www.instagram.com/rodrigocoelhoc/ | D17: =IFERROR(__xludf.DUMMYFUNCTION("""COMPUTED_VALUE"""),133000) -> 133000 | E17: =IFERROR(__xludf.DUMMYFUNCTION("""COMPUTED_VALUE"""),"https://www.tiktok.com/@rodrigocoelhoc") -> https://www.tiktok.com/@rodrigocoelhoc | F17: =IFERROR(__xludf.DUMMYFUNCTION("""COMPUTED_VALUE"""),70000) -> 70000
A18: =IFERROR(__xludf.DUMMYFUNCTION("""COMPUTED_VALUE"""),76331531) -> 76331531 | B18: =IFERROR(__xludf.DUMMYFUNCTION("""COMPUTED_VALUE"""),"especialistaemti") -> especialistaemti | C18: =IFERROR(__xludf.DUMMYFUNCTION("""COMPUTED_VALUE"""),"instagram.com/especialistaemti") -> instagram.com/especialistaemti | D18: =IFERROR(__xludf.DUMMYFUNCTION("""COMPUTED_VALUE"""),53000) -> 53000 | E18: =IFERROR(__xludf.DUMMYFUNCTION("""COMPUTED_VALUE"""),"tiktok.com/especialistaemti") -> tiktok.com/especialistaemti | F18: =IFERROR(__xludf.DUMMYFUNCTION("""COMPUTED_VALUE"""),10000) -> 10000
A19: =IFERROR(__xludf.DUMMYFUNCTION("""COMPUTED_VALUE"""),1454842874) -> 1454842874 | B19: =IFERROR(__xludf.DUMMYFUNCTION("""COMPUTED_VALUE"""),"promocaozinha") -> promocaozinha | C19: =IFERROR(__xludf.DUMMYFUNCTION("""COMPUTED_VALUE"""),"instagram.com/promocaozinha") -> instagram.com/promocaozinha | D19: =IFERROR(__xludf.DUMMYFUNCTION("""COMPUTED_VALUE"""),2600000) -> 2600000 | E19: =IFERROR(__xludf.DUMMYFUNCTION("""COMPUTED_VALUE"""),"tiktok.com/@promocaozinha") -> tiktok.com/@promocaozinha | F19: =IFERROR(__xludf.DUMMYFUNCTION("""COMPUTED_VALUE"""),200000) -> 200000
A20: =IFERROR(__xludf.DUMMYFUNCTION("""COMPUTED_VALUE"""),593029712) -> 593029712 | B20: =IFERROR(__xludf.DUMMYFUNCTION("""COMPUTED_VALUE"""),"pobredasofertas") -> pobredasofertas | C20: =IFERROR(__xludf.DUMMYFUNCTION("""COMPUTED_VALUE"""),"instagram.com/buscopobres") -> instagram.com/buscopobres | D20: =IFERROR(__xludf.DUMMYFUNCTION("""COMPUTED_VALUE"""),81000) -> 81000 | E20: =IFERROR(__xludf.DUMMYFUNCTION("""COMPUTED_VALUE"""),"tiktok.com/buscopobres") -> tiktok.com/buscopobres | F20: =IFERROR(__xludf.DUMMYFUNCTION("""COMPUTED_VALUE"""),1271) -> 1271
A21: =IFERROR(__xludf.DUMMYFUNCTION("""COMPUTED_VALUE"""),207302282) -> 207302282 | B21: =IFERROR(__xludf.DUMMYFUNCTION("""COMPUTED_VALUE"""),"promos4m") -> promos4m | C21: =IFERROR(__xludf.DUMMYFUNCTION("""COMPUTED_VALUE"""),"https://www.instagram.com/promos4m/") -> https://www.instagram.com/promos4m/ | D21: =IFERROR(__xludf.DUMMYFUNCTION("""COMPUTED_VALUE"""),13745) -> 13745 | E21: =IFERROR(__xludf.DUMMYFUNCTION("""COMPUTED_VALUE"""),"https://www.tiktok.com/@promos4m?lang=pt-BR") -> https://www.tiktok.com/@promos4m?lang=pt-BR | F21: =IFERROR(__xludf.DUMMYFUNCTION("""COMPUTED_VALUE"""),2367) -> 2367
A22: =IFERROR(__xludf.DUMMYFUNCTION("""COMPUTED_VALUE"""),322502351) -> 322502351 | B22: =IFERROR(__xludf.DUMMYFUNCTION("""COMPUTED_VALUE"""),"desconto") -> desconto | C22: =IFERROR(__xludf.DUMMYFUNCTION("""COMPUTED_VALUE"""),"https://www.instagram.com/santostecpromo/") -> https://www.instagram.com/santostecpromo/ | D22: =IFERROR(__xludf.DUMMYFUNCTION("""COMPUTED_VALUE"""),700) -> 700 | E22: =IFERROR(__xludf.DUMMYFUNCTION("""COMPUTED_VALUE"""),"https://www.tiktok.com/@santostecpromo") -> https://www.tiktok.com/@santostecpromo | F22: =IFERROR(__xludf.DUMMYFUNCTION("""COMPUTED_VALUE"""),5500) -> 5500
A23: =IFERROR(__xludf.DUMMYFUNCTION("""COMPUTED_VALUE"""),1375138586) -> 1375138586 | B23: =IFERROR(__xludf.DUMMYFUNCTION("""COMPUTED_VALUE"""),"Canaljptech") -> Canaljptech | C23: =IFERROR(__xludf.DUMMYFUNCTION("""COMPUTED_VALUE"""),"https://www.instagram.com/jptechgames/") -> https://www.instagram.com/jptechgames/ | D23: =IFERROR(__xludf.DUMMYFUNCTION("""COMPUTED_VALUE"""),28077) -> 28077 | E23: =IFERROR(__xludf.DUMMYFUNCTION("""COMPUTED_VALUE"""),"https://www.tiktok.com/@jptechgames_") -> https://www.tiktok.com/@jptechgames_ | F23: =IFERROR(__xludf.DUMMYFUNCTION("""COMPUTED_VALUE"""),172000) -> 172000
A24: =IFERROR(__xludf.DUMMYFUNCTION("""COMPUTED_VALUE"""),1366151811) -> 1366151811 | B24: =IFERROR(__xludf.DUMMYFUNCTION("""COMPUTED_VALUE"""),"pcdofafa") -> pcdofafa | C24: =IFERROR(__xludf.DUMMYFUNCTION("""COMPUTED_VALUE"""),"https://www.instagram.com/pcdofafa?igsh=MW15cTUyaDV2a3QwaQ==") -> https://www.instagram.com/pcdofafa?igsh=MW15cTUyaDV2a3QwaQ== | D24: =IFERROR(__xludf.DUMMYFUNCTION("""COMPUTED_VALUE"""),17000) -> 17000 | E24: =IFERROR(__xludf.DUMMYFUNCTION("""COMPUTED_VALUE"""),"https://www.tiktok.com/@pcdofafa?_t=ZM-8yzfN0wUGqz&_r=1") -> https://www.tiktok.com/@pcdofafa?_t=ZM-8yzfN0wUGqz&_r=1 | F24: =IFERROR(__xludf.DUMMYFUNCTION("""COMPUTED_VALUE"""),19000) -> 19000
A25: =IFERROR(__xludf.DUMMYFUNCTION("""COMPUTED_VALUE"""),1473563772) -> 1473563772 | B25: =IFERROR(__xludf.DUMMYFUNCTION("""COMPUTED_VALUE"""),"urubupromo") -> urubupromo | C25: =IFERROR(__xludf.DUMMYFUNCTION("""COMPUTED_VALUE"""),"instagram.com/urubupromo") -> instagram.com/urubupromo | D25: =IFERROR(__xludf.DUMMYFUNCTION("""COMPUTED_VALUE"""),63000) -> 63000
A26: =IFERROR(__xludf.DUMMYFUNCTION("""COMPUTED_VALUE"""),1249172900) -> 1249172900 | B26: =IFERROR(__xludf.DUMMYFUNCTION("""COMPUTED_VALUE"""),"tttech") -> tttech | C26: =IFERROR(__xludf.DUMMYFUNCTION("""COMPUTED_VALUE"""),"https://www.instagram.com/thalissontttech/") -> https://www.instagram.com/thalissontttech/ | D26: =IFERROR(__xludf.DUMMYFUNCTION("""COMPUTED_VALUE"""),20000) -> 20000 | E26: =IFERROR(__xludf.DUMMYFUNCTION("""COMPUTED_VALUE"""),"https://www.tiktok.com/@thalisson_tttech") -> https://www.tiktok.com/@thalisson_tttech | F26: =IFERROR(__xludf.DUMMYFUNCTION("""COMPUTED_VALUE"""),3000) -> 3000
A27: =IFERROR(__xludf.DUMMYFUNCTION("""COMPUTED_VALUE"""),1478114661) -> 1478114661 | B27: =IFERROR(__xludf.DUMMYFUNCTION("""COMPUTED_VALUE"""),"peguepromo") -> peguepromo | C27: =IFERROR(__xludf.DUMMYFUNCTION("""COMPUTED_VALUE"""),"https://www.instagram.com/peguepromo/") -> https://www.instagram.com/peguepromo/ | D27: =IFERROR(__xludf.DUMMYFUNCTION("""COMPUTED_VALUE"""),135000) -> 135000
A28: =IFERROR(__xludf.DUMMYFUNCTION("""COMPUTED_VALUE"""),1231576803) -> 1231576803 | B28: =IFERROR(__xludf.DUMMYFUNCTION("""COMPUTED_VALUE"""),"inovaleo") -> inovaleo | C28: =IFERROR(__xludf.DUMMYFUNCTION("""COMPUTED_VALUE"""),"https://www.instagram.com/inovaleo/?hl=pt-br") -> https://www.instagram.com/inovaleo/?hl=pt-br | D28: =IFERROR(__xludf.DUMMYFUNCTION("""COMPUTED_VALUE"""),492000) -> 492000 | E28: =IFERROR(__xludf.DUMMYFUNCTION("""COMPUTED_VALUE"""),"https://www.tiktok.com/@inovaleo?_t=8ce33tztExC&_r=1") -> https://www.tiktok.com/@inovaleo?_t=8ce33tztExC&_r=1 | F28: =IFERROR(__xludf.DUMMYFUNCTION("""COMPUTED_VALUE"""),134000) -> 134000
A29: =IFERROR(__xludf.DUMMYFUNCTION("""COMPUTED_VALUE"""),1450808630) -> 1450808630 | B29: =IFERROR(__xludf.DUMMYFUNCTION("""COMPUTED_VALUE"""),"agenciarice") -> agenciarice | C29: =IFERROR(__xludf.DUMMYFUNCTION("""COMPUTED_VALUE"""),"https://www.instagram.com/lobaopromo?igsh=MWRsZWlyNWI4bmU1aA==") -> https://www.instagram.com/lobaopromo?igsh=MWRsZWlyNWI4bmU1aA== | D29: =IFERROR(__xludf.DUMMYFUNCTION("""COMPUTED_VALUE"""),12000) -> 12000 | E29: =IFERROR(__xludf.DUMMYFUNCTION("""COMPUTED_VALUE"""),"https://x.com/lobaopromo?s=21") -> https://x.com/lobaopromo?s=21 | F29: =IFERROR(__xludf.DUMMYFUNCTION("""COMPUTED_VALUE"""),224000) -> 224000
A30: =IFERROR(__xludf.DUMMYFUNCTION("""COMPUTED_VALUE"""),1251879558) -> 1251879558 | B30: =IFERROR(__xludf.DUMMYFUNCTION("""COMPUTED_VALUE"""),"qualnotebook") -> qualnotebook | C30: =IFERROR(__xludf.DUMMYFUNCTION("""COMPUTED_VALUE"""),"https://www.instagram.com/qualnotebook/") -> https://www.instagram.com/qualnotebook/ | D30: =IFERROR(__xludf.DUMMYFUNCTION("""COMPUTED_VALUE"""),57000) -> 57000 | E30: =IFERROR(__xludf.DUMMYFUNCTION("""COMPUTED_VALUE"""),"https://www.tiktok.com/@qualnotebook/") -> https://www.tiktok.com/@qualnotebook/ | F30: =IFERROR(__xludf.DUMMYFUNCTION("""COMPUTED_VALUE"""),14000) -> 14000
A31: =IFERROR(__xludf.DUMMYFUNCTION("""COMPUTED_VALUE"""),2345017244) -> 2345017244 | B31: =IFERROR(__xludf.DUMMYFUNCTION("""COMPUTED_VALUE"""),"promosinc") -> promosinc | C31: =IFERROR(__xludf.DUMMYFUNCTION("""COMPUTED_VALUE"""),"https://www.instagram.com/pegar.promo") -> https://www.instagram.com/pegar.promo | D31: =IFERROR(__xludf.DUMMYFUNCTION("""COMPUTED_VALUE"""),140) -> 140
A32: =IFERROR(__xludf.DUMMYFUNCTION("""COMPUTED_VALUE"""),1453452471) -> 1453452471 | B32: =IFERROR(__xludf.DUMMYFUNCTION("""COMPUTED_VALUE"""),"Daniel Reenlsober") -> Daniel Reenlsober | C32: =IFERROR(__xludf.DUMMYFUNCTION("""COMPUTED_VALUE"""),"https://www.instagram.com/danielreen_") -> https://www.instagram.com/danielreen_ | D32: =IFERROR(__xludf.DUMMYFUNCTION("""COMPUTED_VALUE"""),10800) -> 10800 | E32: =IFERROR(__xludf.DUMMYFUNCTION("""COMPUTED_VALUE"""),"https://www.tiktok.com/@danielreen_") -> https://www.tiktok.com/@danielreen_ | F32: =IFERROR(__xludf.DUMMYFUNCTION("""COMPUTED_VALUE"""),2300) -> 2300
A33: =IFERROR(__xludf.DUMMYFUNCTION("""COMPUTED_VALUE"""),1161200505) -> 1161200505 | B33: =IFERROR(__xludf.DUMMYFUNCTION("""COMPUTED_VALUE"""),"mastertechjr") -> mastertechjr | C33: =IFERROR(__xludf.DUMMYFUNCTION("""COMPUTED_VALUE"""),"www.instagran.com/mastertechjr") -> www.instagran.com/mastertechjr | D33: =IFERROR(__xludf.DUMMYFUNCTION("""COMPUTED_VALUE"""),3019) -> 3019
A34: =IFERROR(__xludf.DUMMYFUNCTION("""COMPUTED_VALUE"""),1374758175) -> 1374758175 | B34: =IFERROR(__xludf.DUMMYFUNCTION("""COMPUTED_VALUE"""),"promotop") -> promotop | C34: =IFERROR(__xludf.DUMMYFUNCTION("""COMPUTED_VALUE"""),"https://www.instagram.com/promotopoficial/?hl=pt-br") -> https://www.instagram.com/promotopoficial/?hl=pt-br | D34: =IFERROR(__xludf.DUMMYFUNCTION("""COMPUTED_VALUE"""),31000) -> 31000 | E34: =IFERROR(__xludf.DUMMYFUNCTION("""COMPUTED_VALUE"""),"https://www.tiktok.com/@canalpromotop") -> https://www.tiktok.com/@canalpromotop | F34: =IFERROR(__xludf.DUMMYFUNCTION("""COMPUTED_VALUE"""),2300) -> 2300
A35: =IFERROR(__xludf.DUMMYFUNCTION("""COMPUTED_VALUE"""),268850426) -> 268850426 | B35: =IFERROR(__xludf.DUMMYFUNCTION("""COMPUTED_VALUE"""),"jeffrecomenda") -> jeffrecomenda | C35: =IFERROR(__xludf.DUMMYFUNCTION("""COMPUTED_VALUE"""),"https://www.instagram.com/jeffrecomenda?igsh=czA1bWVubm16M205") -> https://www.instagram.com/jeffrecomenda?igsh=czA1bWVubm16M205 | D35: =IFERROR(__xludf.DUMMYFUNCTION("""COMPUTED_VALUE"""),38000) -> 38000 | E35: =IFERROR(__xludf.DUMMYFUNCTION("""COMPUTED_VALUE"""),"https://www.tiktok.com/@jeffrecomenda?_t=ZM-8yqmv34HBgM&_r=1") -> https://www.tiktok.com/@jeffrecomenda?_t=ZM-8yqmv34HBgM&_r=1 | F35: =IFERROR(__xludf.DUMMYFUNCTION("""COMPUTED_VALUE"""),27000) -> 27000
A36: =IFERROR(__xludf.DUMMYFUNCTION("""COMPUTED_VALUE"""),1426808500) -> 1426808500 | B36: =IFERROR(__xludf.DUMMYFUNCTION("""COMPUTED_VALUE"""),"promoimperdivel") -> promoimperdivel | C36: =IFERROR(__xludf.DUMMYFUNCTION("""COMPUTED_VALUE"""),"instagram.com/promoimperdivel_") -> instagram.com/promoimperdivel_ | D36: =IFERROR(__xludf.DUMMYFUNCTION("""COMPUTED_VALUE"""),8000) -> 8000
A37: =IFERROR(__xludf.DUMMYFUNCTION("""COMPUTED_VALUE"""),1114585317) -> 1114585317 | B37: =IFERROR(__xludf.DUMMYFUNCTION("""COMPUTED_VALUE"""),"bench promos") -> bench promos | C37: =IFERROR(__xludf.DUMMYFUNCTION("""COMPUTED_VALUE"""),"https://www.instagram.com/lucas.ishii/") -> https://www.instagram.com/lucas.ishii/ | D37: =IFERROR(__xludf.DUMMYFUNCTION("""COMPUTED_VALUE"""),53200) -> 53200 | E37: =IFERROR(__xludf.DUMMYFUNCTION("""COMPUTED_VALUE"""),"https://www.tiktok.com/@lucas_ishii?lang=pt-BR") -> https://www.tiktok.com/@lucas_ishii?lang=pt-BR | F37: =IFERROR(__xludf.DUMMYFUNCTION("""COMPUTED_VALUE"""),111700) -> 111700
A38: =IFERROR(__xludf.DUMMYFUNCTION("""COMPUTED_VALUE"""),1370750164) -> 1370750164 | B38: =IFERROR(__xludf.DUMMYFUNCTION("""COMPUTED_VALUE"""),"switchxz") -> switchxz | C38: =IFERROR(__xludf.DUMMYFUNCTION("""COMPUTED_VALUE"""),"https://www.instagram.com/linksbrazil (não utilizo)") -> https://www.instagram.com/linksbrazil (não utilizo) | D38: =IFERROR(__xludf.DUMMYFUNCTION("""COMPUTED_VALUE"""),158) -> 158
A39: =IFERROR(__xludf.DUMMYFUNCTION("""COMPUTED_VALUE"""),251645009) -> 251645009 | B39: =IFERROR(__xludf.DUMMYFUNCTION("""COMPUTED_VALUE"""),"novosprodutos") -> novosprodutos | C39: =IFERROR(__xludf.DUMMYFUNCTION("""COMPUTED_VALUE"""),"https://www.instagram.com/novosprodutos") -> https://www.instagram.com/novosprodutos | D39: =IFERROR(__xludf.DUMMYFUNCTION("""COMPUTED_VALUE"""),4000000) -> 4000000
A40: =IFERROR(__xludf.DUMMYFUNCTION("""COMPUTED_VALUE"""),263391604) -> 263391604 | B40: =IFERROR(__xludf.DUMMYFUNCTION("""COMPUTED_VALUE"""),"so_promocoesdodia") -> so_promocoesdodia | C40: =IFERROR(__xludf.DUMMYFUNCTION("""COMPUTED_VALUE"""),"https://www.instagram.com/so_promocoesdodia?igsh=MTBieDVweDN3eXN5eg==") -> https://www.instagram.com/so_promocoesdodia?igsh=MTBieDVweDN3eXN5eg== | D40: =IFERROR(__xludf.DUMMYFUNCTION("""COMPUTED_VALUE"""),950000) -> 950000
...
